{
  "nbformat": 4,
  "nbformat_minor": 0,
  "metadata": {
    "accelerator": "GPU",
    "colab": {
      "name": "Run SceneDetect.ipynb",
      "provenance": [],
      "collapsed_sections": []
    },
    "kernelspec": {
      "display_name": "Python 3",
      "name": "python3"
    }
  },
  "cells": [
    {
      "cell_type": "markdown",
      "metadata": {
        "id": "NsoCO9TaM87A"
      },
      "source": [
        "**Install Scene Detect and detecet Scenes**"
      ]
    },
    {
      "cell_type": "code",
      "metadata": {
        "colab": {
          "base_uri": "https://localhost:8080/"
        },
        "id": "6KkHOLitqcGh",
        "outputId": "673e5398-2d21-45f4-b1d8-5ba6e2fc3e59"
      },
      "source": [
        "!pip install scenedetect[opencv,progress_bar]"
      ],
      "execution_count": null,
      "outputs": [
        {
          "output_type": "stream",
          "name": "stdout",
          "text": [
            "Collecting scenedetect[opencv,progress_bar]\n",
            "  Downloading scenedetect-0.5.6.1-py2.py3-none-any.whl (98 kB)\n",
            "\u001b[?25l\r\u001b[K     |███▎                            | 10 kB 852 kB/s eta 0:00:01\r\u001b[K     |██████▋                         | 20 kB 1.7 MB/s eta 0:00:01\r\u001b[K     |██████████                      | 30 kB 2.4 MB/s eta 0:00:01\r\u001b[K     |█████████████▎                  | 40 kB 3.2 MB/s eta 0:00:01\r\u001b[K     |████████████████▋               | 51 kB 3.9 MB/s eta 0:00:01\r\u001b[K     |████████████████████            | 61 kB 4.7 MB/s eta 0:00:01\r\u001b[K     |███████████████████████▏        | 71 kB 3.8 MB/s eta 0:00:01\r\u001b[K     |██████████████████████████▌     | 81 kB 3.6 MB/s eta 0:00:01\r\u001b[K     |█████████████████████████████▉  | 92 kB 4.0 MB/s eta 0:00:01\r\u001b[K     |████████████████████████████████| 98 kB 3.0 MB/s \n",
            "\u001b[33mWARNING: scenedetect 0.5.6.1 does not provide the extra 'progress_bar'\u001b[0m\n",
            "\u001b[?25hRequirement already satisfied: Click in /usr/local/lib/python3.7/dist-packages (from scenedetect[opencv,progress_bar]) (7.1.2)\n",
            "Requirement already satisfied: tqdm in /usr/local/lib/python3.7/dist-packages (from scenedetect[opencv,progress_bar]) (4.63.0)\n",
            "Requirement already satisfied: numpy in /usr/local/lib/python3.7/dist-packages (from scenedetect[opencv,progress_bar]) (1.21.5)\n",
            "Requirement already satisfied: opencv-python in /usr/local/lib/python3.7/dist-packages (from scenedetect[opencv,progress_bar]) (4.1.2.30)\n",
            "Installing collected packages: scenedetect\n",
            "Successfully installed scenedetect-0.5.6.1\n"
          ]
        }
      ]
    },
    {
      "cell_type": "markdown",
      "metadata": {
        "id": "8vTBaqHNNFiI"
      },
      "source": [
        "mount your Gdrive to Colab"
      ]
    },
    {
      "cell_type": "code",
      "metadata": {
        "colab": {
          "base_uri": "https://localhost:8080/"
        },
        "id": "-H0vjLC4rFUH",
        "outputId": "9179b293-cbae-44a4-f51e-e477886bca66"
      },
      "source": [
        "from google.colab import drive\n",
        "\n",
        "drive.mount('/content/gdrive/')\n",
        "\n"
      ],
      "execution_count": null,
      "outputs": [
        {
          "output_type": "stream",
          "name": "stdout",
          "text": [
            "Mounted at /content/gdrive/\n"
          ]
        }
      ]
    },
    {
      "cell_type": "code",
      "metadata": {
        "colab": {
          "base_uri": "https://localhost:8080/"
        },
        "id": "w7Rz3yQv2PKr",
        "outputId": "ff07a6e3-5d95-497e-96f2-653a78ec82d1"
      },
      "source": [
        "# Change directory where your film's file is located.\n",
        "%cd /content/gdrive/MyDrive/GoodBadUgly"
      ],
      "execution_count": null,
      "outputs": [
        {
          "output_type": "stream",
          "name": "stdout",
          "text": [
            "/content/gdrive/MyDrive/GoodBadUgly\n"
          ]
        }
      ]
    },
    {
      "cell_type": "code",
      "metadata": {
        "id": "TnZw0te9qlQC"
      },
      "source": [
        "#list the files in the directory\n",
        "import os\n",
        "#path = \"/content/gdrive/My Drive/filmUpload_film/\"\n",
        "files = os.listdir()\n"
      ],
      "execution_count": null,
      "outputs": []
    },
    {
      "cell_type": "code",
      "source": [
        "# Check the last file in the list. It should be your film.\n",
        "files[-1]"
      ],
      "metadata": {
        "id": "Z9IsqRpQbJ5G",
        "colab": {
          "base_uri": "https://localhost:8080/",
          "height": 36
        },
        "outputId": "305f4e36-172c-45e7-ed2f-b6cbc14c0377"
      },
      "execution_count": null,
      "outputs": [
        {
          "output_type": "execute_result",
          "data": {
            "text/plain": [
              "'The.Good.The.Bad.The.Ugly.1966.mkv'"
            ],
            "application/vnd.google.colaboratory.intrinsic+json": {
              "type": "string"
            }
          },
          "metadata": {},
          "execution_count": 6
        }
      ]
    },
    {
      "cell_type": "code",
      "metadata": {
        "colab": {
          "base_uri": "https://localhost:8080/"
        },
        "id": "HOqqkOSozZ4e",
        "outputId": "b5512b02-0ce9-487d-8d42-cbc84d136bbe"
      },
      "source": [
        "# Run SceneDetect on the files in the folder. Print out the file's name.\n",
        "for file in files:\n",
        "  os.system(f\"scenedetect -i {file} -o output_dir detect-content list-scenes save-images\")\n",
        "  print(file)"
      ],
      "execution_count": null,
      "outputs": [
        {
          "output_type": "stream",
          "name": "stdout",
          "text": [
            "The.Good.The.Bad.The.Ugly.1966.mkv\n"
          ]
        }
      ]
    },
    {
      "cell_type": "code",
      "source": [
        "# move the files to a desired folder.\n",
        "import shutil\n",
        "source = r'/content/gdrive/MyDrive/OnceUponATime'\n",
        "dest = r'/content/gdrive/MyDrive/Marton Mátyás szakdolgozat programok/filmek/'\n",
        "shutil.move(source,dest)"
      ],
      "metadata": {
        "colab": {
          "base_uri": "https://localhost:8080/",
          "height": 1000
        },
        "id": "U3Z_ZxQqtrIH",
        "outputId": "aa3f9c1c-b04d-4d55-de85-12bdc3be5ffa"
      },
      "execution_count": null,
      "outputs": [
        {
          "output_type": "stream",
          "name": "stderr",
          "text": [
            "ERROR:root:Internal Python error in the inspect module.\n",
            "Below is the traceback from this internal error.\n",
            "\n",
            "ERROR:root:Internal Python error in the inspect module.\n",
            "Below is the traceback from this internal error.\n",
            "\n"
          ]
        },
        {
          "output_type": "stream",
          "name": "stdout",
          "text": [
            "Traceback (most recent call last):\n",
            "  File \"/usr/lib/python3.7/shutil.py\", line 566, in move\n",
            "    os.rename(src, real_dst)\n",
            "FileNotFoundError: [Errno 2] No such file or directory: '/content/gdrive/MyDrive/OnceUponATime/output_dir/' -> '/content/gdrive/MyDrive/Marton Mátyás szakdolgozat programok/filmek/output_dir'\n",
            "\n",
            "During handling of the above exception, another exception occurred:\n",
            "\n",
            "Traceback (most recent call last):\n",
            "  File \"/usr/local/lib/python3.7/dist-packages/IPython/core/interactiveshell.py\", line 2882, in run_code\n",
            "    exec(code_obj, self.user_global_ns, self.user_ns)\n",
            "  File \"<ipython-input-6-9a8fb9cbaf69>\", line 4, in <module>\n",
            "    shutil.move(source,dest)\n",
            "  File \"/usr/lib/python3.7/shutil.py\", line 580, in move\n",
            "    copy_function(src, real_dst)\n",
            "  File \"/usr/lib/python3.7/shutil.py\", line 266, in copy2\n",
            "    copyfile(src, dst, follow_symlinks=follow_symlinks)\n",
            "  File \"/usr/lib/python3.7/shutil.py\", line 120, in copyfile\n",
            "    with open(src, 'rb') as fsrc:\n",
            "FileNotFoundError: [Errno 2] No such file or directory: '/content/gdrive/MyDrive/OnceUponATime/output_dir/'\n",
            "\n",
            "During handling of the above exception, another exception occurred:\n",
            "\n",
            "Traceback (most recent call last):\n",
            "  File \"/usr/local/lib/python3.7/dist-packages/IPython/core/interactiveshell.py\", line 1823, in showtraceback\n",
            "    stb = value._render_traceback_()\n",
            "AttributeError: 'FileNotFoundError' object has no attribute '_render_traceback_'\n",
            "\n",
            "During handling of the above exception, another exception occurred:\n",
            "\n",
            "Traceback (most recent call last):\n",
            "  File \"/usr/local/lib/python3.7/dist-packages/IPython/core/ultratb.py\", line 1132, in get_records\n",
            "    return _fixed_getinnerframes(etb, number_of_lines_of_context, tb_offset)\n",
            "  File \"/usr/local/lib/python3.7/dist-packages/IPython/core/ultratb.py\", line 313, in wrapped\n",
            "    return f(*args, **kwargs)\n",
            "  File \"/usr/local/lib/python3.7/dist-packages/IPython/core/ultratb.py\", line 358, in _fixed_getinnerframes\n",
            "    records = fix_frame_records_filenames(inspect.getinnerframes(etb, context))\n",
            "  File \"/usr/lib/python3.7/inspect.py\", line 1502, in getinnerframes\n",
            "    frameinfo = (tb.tb_frame,) + getframeinfo(tb, context)\n",
            "  File \"/usr/lib/python3.7/inspect.py\", line 1460, in getframeinfo\n",
            "    filename = getsourcefile(frame) or getfile(frame)\n",
            "  File \"/usr/lib/python3.7/inspect.py\", line 696, in getsourcefile\n",
            "    if getattr(getmodule(object, filename), '__loader__', None) is not None:\n",
            "  File \"/usr/lib/python3.7/inspect.py\", line 725, in getmodule\n",
            "    file = getabsfile(object, _filename)\n",
            "  File \"/usr/lib/python3.7/inspect.py\", line 709, in getabsfile\n",
            "    return os.path.normcase(os.path.abspath(_filename))\n",
            "  File \"/usr/lib/python3.7/posixpath.py\", line 383, in abspath\n",
            "    cwd = os.getcwd()\n",
            "FileNotFoundError: [Errno 2] No such file or directory\n",
            "Traceback (most recent call last):\n",
            "  File \"/usr/lib/python3.7/shutil.py\", line 566, in move\n",
            "    os.rename(src, real_dst)\n",
            "FileNotFoundError: [Errno 2] No such file or directory: '/content/gdrive/MyDrive/OnceUponATime/output_dir/' -> '/content/gdrive/MyDrive/Marton Mátyás szakdolgozat programok/filmek/output_dir'\n",
            "\n",
            "During handling of the above exception, another exception occurred:\n",
            "\n",
            "Traceback (most recent call last):\n",
            "  File \"/usr/local/lib/python3.7/dist-packages/IPython/core/interactiveshell.py\", line 2882, in run_code\n",
            "    exec(code_obj, self.user_global_ns, self.user_ns)\n",
            "  File \"<ipython-input-6-9a8fb9cbaf69>\", line 4, in <module>\n",
            "    shutil.move(source,dest)\n",
            "  File \"/usr/lib/python3.7/shutil.py\", line 580, in move\n",
            "    copy_function(src, real_dst)\n",
            "  File \"/usr/lib/python3.7/shutil.py\", line 266, in copy2\n",
            "    copyfile(src, dst, follow_symlinks=follow_symlinks)\n",
            "  File \"/usr/lib/python3.7/shutil.py\", line 120, in copyfile\n",
            "    with open(src, 'rb') as fsrc:\n",
            "FileNotFoundError: [Errno 2] No such file or directory: '/content/gdrive/MyDrive/OnceUponATime/output_dir/'\n",
            "\n",
            "During handling of the above exception, another exception occurred:\n",
            "\n",
            "Traceback (most recent call last):\n",
            "  File \"/usr/local/lib/python3.7/dist-packages/IPython/core/interactiveshell.py\", line 1823, in showtraceback\n",
            "    stb = value._render_traceback_()\n",
            "AttributeError: 'FileNotFoundError' object has no attribute '_render_traceback_'\n",
            "\n",
            "During handling of the above exception, another exception occurred:\n",
            "\n",
            "Traceback (most recent call last):\n",
            "  File \"/usr/local/lib/python3.7/dist-packages/IPython/core/interactiveshell.py\", line 2828, in run_ast_nodes\n",
            "    if self.run_code(code, result):\n",
            "  File \"/usr/local/lib/python3.7/dist-packages/IPython/core/interactiveshell.py\", line 2899, in run_code\n",
            "    self.showtraceback()\n",
            "  File \"/usr/local/lib/python3.7/dist-packages/IPython/core/interactiveshell.py\", line 1826, in showtraceback\n",
            "    value, tb, tb_offset=tb_offset)\n",
            "  File \"/usr/local/lib/python3.7/dist-packages/IPython/core/ultratb.py\", line 1411, in structured_traceback\n",
            "    self, etype, value, tb, tb_offset, number_of_lines_of_context)\n",
            "  File \"/usr/local/lib/python3.7/dist-packages/IPython/core/ultratb.py\", line 1319, in structured_traceback\n",
            "    self, etype, value, tb, tb_offset, number_of_lines_of_context\n",
            "  File \"/usr/local/lib/python3.7/dist-packages/IPython/core/ultratb.py\", line 1182, in structured_traceback\n",
            "    formatted_exceptions += self.prepare_chained_exception_message(evalue.__cause__)\n",
            "TypeError: can only concatenate str (not \"list\") to str\n",
            "\n",
            "During handling of the above exception, another exception occurred:\n",
            "\n",
            "Traceback (most recent call last):\n",
            "  File \"/usr/local/lib/python3.7/dist-packages/IPython/core/interactiveshell.py\", line 1823, in showtraceback\n",
            "    stb = value._render_traceback_()\n",
            "AttributeError: 'TypeError' object has no attribute '_render_traceback_'\n",
            "\n",
            "During handling of the above exception, another exception occurred:\n",
            "\n",
            "Traceback (most recent call last):\n",
            "  File \"/usr/local/lib/python3.7/dist-packages/IPython/core/ultratb.py\", line 1132, in get_records\n",
            "    return _fixed_getinnerframes(etb, number_of_lines_of_context, tb_offset)\n",
            "  File \"/usr/local/lib/python3.7/dist-packages/IPython/core/ultratb.py\", line 313, in wrapped\n",
            "    return f(*args, **kwargs)\n",
            "  File \"/usr/local/lib/python3.7/dist-packages/IPython/core/ultratb.py\", line 358, in _fixed_getinnerframes\n",
            "    records = fix_frame_records_filenames(inspect.getinnerframes(etb, context))\n",
            "  File \"/usr/lib/python3.7/inspect.py\", line 1502, in getinnerframes\n",
            "    frameinfo = (tb.tb_frame,) + getframeinfo(tb, context)\n",
            "  File \"/usr/lib/python3.7/inspect.py\", line 1460, in getframeinfo\n",
            "    filename = getsourcefile(frame) or getfile(frame)\n",
            "  File \"/usr/lib/python3.7/inspect.py\", line 696, in getsourcefile\n",
            "    if getattr(getmodule(object, filename), '__loader__', None) is not None:\n",
            "  File \"/usr/lib/python3.7/inspect.py\", line 725, in getmodule\n",
            "    file = getabsfile(object, _filename)\n",
            "  File \"/usr/lib/python3.7/inspect.py\", line 709, in getabsfile\n",
            "    return os.path.normcase(os.path.abspath(_filename))\n",
            "  File \"/usr/lib/python3.7/posixpath.py\", line 383, in abspath\n",
            "    cwd = os.getcwd()\n",
            "FileNotFoundError: [Errno 2] No such file or directory\n"
          ]
        },
        {
          "output_type": "error",
          "ename": "TypeError",
          "evalue": "ignored",
          "traceback": [
            "\u001b[0;31m---------------------------------------------------------------------------\u001b[0m",
            "\u001b[0;31mFileNotFoundError\u001b[0m                         Traceback (most recent call last)",
            "\u001b[0;32m/usr/lib/python3.7/shutil.py\u001b[0m in \u001b[0;36mmove\u001b[0;34m(src, dst, copy_function)\u001b[0m\n\u001b[1;32m    565\u001b[0m     \u001b[0;32mtry\u001b[0m\u001b[0;34m:\u001b[0m\u001b[0;34m\u001b[0m\u001b[0;34m\u001b[0m\u001b[0m\n\u001b[0;32m--> 566\u001b[0;31m         \u001b[0mos\u001b[0m\u001b[0;34m.\u001b[0m\u001b[0mrename\u001b[0m\u001b[0;34m(\u001b[0m\u001b[0msrc\u001b[0m\u001b[0;34m,\u001b[0m \u001b[0mreal_dst\u001b[0m\u001b[0;34m)\u001b[0m\u001b[0;34m\u001b[0m\u001b[0;34m\u001b[0m\u001b[0m\n\u001b[0m\u001b[1;32m    567\u001b[0m     \u001b[0;32mexcept\u001b[0m \u001b[0mOSError\u001b[0m\u001b[0;34m:\u001b[0m\u001b[0;34m\u001b[0m\u001b[0;34m\u001b[0m\u001b[0m\n",
            "\u001b[0;31mFileNotFoundError\u001b[0m: [Errno 2] No such file or directory: '/content/gdrive/MyDrive/OnceUponATime/output_dir/' -> '/content/gdrive/MyDrive/Marton Mátyás szakdolgozat programok/filmek/output_dir'",
            "\nDuring handling of the above exception, another exception occurred:\n",
            "\nDuring handling of the above exception, another exception occurred:\n",
            "\u001b[0;31mAttributeError\u001b[0m                            Traceback (most recent call last)",
            "\u001b[0;32m/usr/local/lib/python3.7/dist-packages/IPython/core/interactiveshell.py\u001b[0m in \u001b[0;36mshowtraceback\u001b[0;34m(self, exc_tuple, filename, tb_offset, exception_only)\u001b[0m\n\u001b[1;32m   1822\u001b[0m                         \u001b[0;31m# in the engines. This should return a list of strings.\u001b[0m\u001b[0;34m\u001b[0m\u001b[0;34m\u001b[0m\u001b[0;34m\u001b[0m\u001b[0m\n\u001b[0;32m-> 1823\u001b[0;31m                         \u001b[0mstb\u001b[0m \u001b[0;34m=\u001b[0m \u001b[0mvalue\u001b[0m\u001b[0;34m.\u001b[0m\u001b[0m_render_traceback_\u001b[0m\u001b[0;34m(\u001b[0m\u001b[0;34m)\u001b[0m\u001b[0;34m\u001b[0m\u001b[0;34m\u001b[0m\u001b[0m\n\u001b[0m\u001b[1;32m   1824\u001b[0m                     \u001b[0;32mexcept\u001b[0m \u001b[0mException\u001b[0m\u001b[0;34m:\u001b[0m\u001b[0;34m\u001b[0m\u001b[0;34m\u001b[0m\u001b[0m\n",
            "\u001b[0;31mAttributeError\u001b[0m: 'FileNotFoundError' object has no attribute '_render_traceback_'",
            "\nDuring handling of the above exception, another exception occurred:\n",
            "\u001b[0;31mTypeError\u001b[0m                                 Traceback (most recent call last)",
            "\u001b[0;32m/usr/local/lib/python3.7/dist-packages/IPython/core/interactiveshell.py\u001b[0m in \u001b[0;36mrun_code\u001b[0;34m(self, code_obj, result)\u001b[0m\n\u001b[1;32m   2897\u001b[0m             \u001b[0;32mif\u001b[0m \u001b[0mresult\u001b[0m \u001b[0;32mis\u001b[0m \u001b[0;32mnot\u001b[0m \u001b[0;32mNone\u001b[0m\u001b[0;34m:\u001b[0m\u001b[0;34m\u001b[0m\u001b[0;34m\u001b[0m\u001b[0m\n\u001b[1;32m   2898\u001b[0m                 \u001b[0mresult\u001b[0m\u001b[0;34m.\u001b[0m\u001b[0merror_in_exec\u001b[0m \u001b[0;34m=\u001b[0m \u001b[0msys\u001b[0m\u001b[0;34m.\u001b[0m\u001b[0mexc_info\u001b[0m\u001b[0;34m(\u001b[0m\u001b[0;34m)\u001b[0m\u001b[0;34m[\u001b[0m\u001b[0;36m1\u001b[0m\u001b[0;34m]\u001b[0m\u001b[0;34m\u001b[0m\u001b[0;34m\u001b[0m\u001b[0m\n\u001b[0;32m-> 2899\u001b[0;31m             \u001b[0mself\u001b[0m\u001b[0;34m.\u001b[0m\u001b[0mshowtraceback\u001b[0m\u001b[0;34m(\u001b[0m\u001b[0;34m)\u001b[0m\u001b[0;34m\u001b[0m\u001b[0;34m\u001b[0m\u001b[0m\n\u001b[0m\u001b[1;32m   2900\u001b[0m         \u001b[0;32melse\u001b[0m\u001b[0;34m:\u001b[0m\u001b[0;34m\u001b[0m\u001b[0;34m\u001b[0m\u001b[0m\n\u001b[1;32m   2901\u001b[0m             \u001b[0moutflag\u001b[0m \u001b[0;34m=\u001b[0m \u001b[0;36m0\u001b[0m\u001b[0;34m\u001b[0m\u001b[0;34m\u001b[0m\u001b[0m\n",
            "\u001b[0;32m/usr/local/lib/python3.7/dist-packages/IPython/core/interactiveshell.py\u001b[0m in \u001b[0;36mshowtraceback\u001b[0;34m(self, exc_tuple, filename, tb_offset, exception_only)\u001b[0m\n\u001b[1;32m   1824\u001b[0m                     \u001b[0;32mexcept\u001b[0m \u001b[0mException\u001b[0m\u001b[0;34m:\u001b[0m\u001b[0;34m\u001b[0m\u001b[0;34m\u001b[0m\u001b[0m\n\u001b[1;32m   1825\u001b[0m                         stb = self.InteractiveTB.structured_traceback(etype,\n\u001b[0;32m-> 1826\u001b[0;31m                                             value, tb, tb_offset=tb_offset)\n\u001b[0m\u001b[1;32m   1827\u001b[0m \u001b[0;34m\u001b[0m\u001b[0m\n\u001b[1;32m   1828\u001b[0m                     \u001b[0mself\u001b[0m\u001b[0;34m.\u001b[0m\u001b[0m_showtraceback\u001b[0m\u001b[0;34m(\u001b[0m\u001b[0metype\u001b[0m\u001b[0;34m,\u001b[0m \u001b[0mvalue\u001b[0m\u001b[0;34m,\u001b[0m \u001b[0mstb\u001b[0m\u001b[0;34m)\u001b[0m\u001b[0;34m\u001b[0m\u001b[0;34m\u001b[0m\u001b[0m\n",
            "\u001b[0;32m/usr/local/lib/python3.7/dist-packages/IPython/core/ultratb.py\u001b[0m in \u001b[0;36mstructured_traceback\u001b[0;34m(self, etype, value, tb, tb_offset, number_of_lines_of_context)\u001b[0m\n\u001b[1;32m   1409\u001b[0m         \u001b[0mself\u001b[0m\u001b[0;34m.\u001b[0m\u001b[0mtb\u001b[0m \u001b[0;34m=\u001b[0m \u001b[0mtb\u001b[0m\u001b[0;34m\u001b[0m\u001b[0;34m\u001b[0m\u001b[0m\n\u001b[1;32m   1410\u001b[0m         return FormattedTB.structured_traceback(\n\u001b[0;32m-> 1411\u001b[0;31m             self, etype, value, tb, tb_offset, number_of_lines_of_context)\n\u001b[0m\u001b[1;32m   1412\u001b[0m \u001b[0;34m\u001b[0m\u001b[0m\n\u001b[1;32m   1413\u001b[0m \u001b[0;34m\u001b[0m\u001b[0m\n",
            "\u001b[0;32m/usr/local/lib/python3.7/dist-packages/IPython/core/ultratb.py\u001b[0m in \u001b[0;36mstructured_traceback\u001b[0;34m(self, etype, value, tb, tb_offset, number_of_lines_of_context)\u001b[0m\n\u001b[1;32m   1317\u001b[0m             \u001b[0;31m# Verbose modes need a full traceback\u001b[0m\u001b[0;34m\u001b[0m\u001b[0;34m\u001b[0m\u001b[0;34m\u001b[0m\u001b[0m\n\u001b[1;32m   1318\u001b[0m             return VerboseTB.structured_traceback(\n\u001b[0;32m-> 1319\u001b[0;31m                 \u001b[0mself\u001b[0m\u001b[0;34m,\u001b[0m \u001b[0metype\u001b[0m\u001b[0;34m,\u001b[0m \u001b[0mvalue\u001b[0m\u001b[0;34m,\u001b[0m \u001b[0mtb\u001b[0m\u001b[0;34m,\u001b[0m \u001b[0mtb_offset\u001b[0m\u001b[0;34m,\u001b[0m \u001b[0mnumber_of_lines_of_context\u001b[0m\u001b[0;34m\u001b[0m\u001b[0;34m\u001b[0m\u001b[0m\n\u001b[0m\u001b[1;32m   1320\u001b[0m             )\n\u001b[1;32m   1321\u001b[0m         \u001b[0;32melse\u001b[0m\u001b[0;34m:\u001b[0m\u001b[0;34m\u001b[0m\u001b[0;34m\u001b[0m\u001b[0m\n",
            "\u001b[0;32m/usr/local/lib/python3.7/dist-packages/IPython/core/ultratb.py\u001b[0m in \u001b[0;36mstructured_traceback\u001b[0;34m(self, etype, evalue, etb, tb_offset, number_of_lines_of_context)\u001b[0m\n\u001b[1;32m   1180\u001b[0m             \u001b[0mexception\u001b[0m \u001b[0;34m=\u001b[0m \u001b[0mself\u001b[0m\u001b[0;34m.\u001b[0m\u001b[0mget_parts_of_chained_exception\u001b[0m\u001b[0;34m(\u001b[0m\u001b[0mevalue\u001b[0m\u001b[0;34m)\u001b[0m\u001b[0;34m\u001b[0m\u001b[0;34m\u001b[0m\u001b[0m\n\u001b[1;32m   1181\u001b[0m             \u001b[0;32mif\u001b[0m \u001b[0mexception\u001b[0m\u001b[0;34m:\u001b[0m\u001b[0;34m\u001b[0m\u001b[0;34m\u001b[0m\u001b[0m\n\u001b[0;32m-> 1182\u001b[0;31m                 \u001b[0mformatted_exceptions\u001b[0m \u001b[0;34m+=\u001b[0m \u001b[0mself\u001b[0m\u001b[0;34m.\u001b[0m\u001b[0mprepare_chained_exception_message\u001b[0m\u001b[0;34m(\u001b[0m\u001b[0mevalue\u001b[0m\u001b[0;34m.\u001b[0m\u001b[0m__cause__\u001b[0m\u001b[0;34m)\u001b[0m\u001b[0;34m\u001b[0m\u001b[0;34m\u001b[0m\u001b[0m\n\u001b[0m\u001b[1;32m   1183\u001b[0m                 \u001b[0metype\u001b[0m\u001b[0;34m,\u001b[0m \u001b[0mevalue\u001b[0m\u001b[0;34m,\u001b[0m \u001b[0metb\u001b[0m \u001b[0;34m=\u001b[0m \u001b[0mexception\u001b[0m\u001b[0;34m\u001b[0m\u001b[0;34m\u001b[0m\u001b[0m\n\u001b[1;32m   1184\u001b[0m             \u001b[0;32melse\u001b[0m\u001b[0;34m:\u001b[0m\u001b[0;34m\u001b[0m\u001b[0;34m\u001b[0m\u001b[0m\n",
            "\u001b[0;31mTypeError\u001b[0m: can only concatenate str (not \"list\") to str"
          ]
        }
      ]
    },
    {
      "cell_type": "code",
      "metadata": {
        "id": "rUmW4fIFOCZZ"
      },
      "source": [
        ""
      ],
      "execution_count": null,
      "outputs": []
    }
  ]
}